[31m[1mERROR   [0m sqlalchemy.pool.impl.QueuePool:base.py:1010 Exception during reset or similar
Traceback (most recent call last):
  File "C:\Users\ÐŸÐ¾Ð»ÑŒÐ·Ð¾Ð²Ð°Ñ‚ÐµÐ»ÑŒ\AppData\Local\Packages\PythonSoftwareFoundation.Python.3.11_qbz5n2kfra8p0\LocalCache\local-packages\Python311\site-packages\sqlalchemy\pool\base.py", line 988, in _finalize_fairy
    fairy._reset(
  File "C:\Users\ÐŸÐ¾Ð»ÑŒÐ·Ð¾Ð²Ð°Ñ‚ÐµÐ»ÑŒ\AppData\Local\Packages\PythonSoftwareFoundation.Python.3.11_qbz5n2kfra8p0\LocalCache\local-packages\Python311\site-packages\sqlalchemy\pool\base.py", line 1436, in _reset
    pool._dialect.do_rollback(self)
  File "C:\Users\ÐŸÐ¾Ð»ÑŒÐ·Ð¾Ð²Ð°Ñ‚ÐµÐ»ÑŒ\AppData\Local\Packages\PythonSoftwareFoundation.Python.3.11_qbz5n2kfra8p0\LocalCache\local-packages\Python311\site-packages\sqlalchemy\engine\default.py", line 691, in do_rollback
    dbapi_connection.rollback()
psycopg2.OperationalError: SSL connection has been closed unexpectedly